Workbook

Sheet 1 Raw Data
A1: STEP 1 — RAW DATA EXTRACTION (all values in USD millions)
A2: 1A — Company Master
A3: # | B3: Company | C3: Ticker | D3: FY End (Current) | E3: FY End (Prior) | F3: Standard | G3: Source Currency | H3: FX Rate / Notes
A4: 1 | B4: NVIDIA | C4: NVDA | D4: Jan 26 2025 (FY2025) | E4: Jan 28 2024 (FY2024) | F4: US GAAP | G4: USD | H4: —
A5: 2 | B5: AMD | C5: AMD | D5: Dec 28 2024 | E5: Dec 30 2023 | F5: US GAAP | G5: USD | H5: —
A6: 3 | B6: Intel | C6: INTC | D6: Dec 28 2024 | E6: Dec 30 2023 | F6: US GAAP | G6: USD | H6: —
A7: 4 | B7: Texas Instruments | C7: TXN | D7: Dec 31 2024 | E7: Dec 31 2023 | F7: US GAAP | G7: USD | H7: —
A8: 5 | B8: Qualcomm | C8: QCOM | D8: Sep 29 2024 | E8: Sep 24 2023 | F8: US GAAP | G8: USD | H8: —
A9: 6 | B9: NXP Semiconductors | C9: NXPI | D9: Dec 31 2024 | E9: Dec 31 2023 | F9: US GAAP | G9: USD | H9: —
A10: 7 | B10: TSMC | C10: TSM | D10: Dec 31 2024 | E10: Dec 31 2023 | F10: IFRS | G10: TWD | H10: FY2024: 32.0 TWD/USD; FY2023: 31.1 TWD/USD [A]
A11: 8 | B11: Micron Technology | C11: MU | D11: Aug 29 2024 | E11: Aug 31 2023 | F11: US GAAP | G11: USD | H11: — (⚠ FY23 gross loss)
A12: 9 | B12: STMicroelectronics | C12: STM | D12: Dec 31 2024 | E12: Dec 31 2023 | F12: IFRS | G12: USD | H12: Reported in USD
A13: 10 | B13: Infineon Technologies | C13: IFX | D13: Sep 30 2024 | E13: Sep 30 2023 | F13: IFRS | G13: EUR | H13: FY2024: 1.085 USD/EUR; FY2023: 1.082 USD/EUR [A]
A15: 1B — Income Statement Data (USD M)
A16: Company | B16: Revenue CY | C16: Revenue PY | D16: COGS CY | E16: COGS PY | F16: Gross Margin CY | G16: Gross Margin PY | H16: COGS Method | I16: Flag
A17: NVIDIA | B17: 130497 | C17: 60922 | D17: 36998 | E17: 16621 | F17: 71.7% | G17: 72.7% | H17: Directly stated
A18: AMD | B18: 25785 | C18: 22680 | D18: 12408 | E18: 11550 | F18: 51.9% | G18: 49.1% | H18: Directly stated
A19: Intel | B19: 53101 | C19: 54228 | D19: 35737 | E19: 31021 | F19: 32.7% | G19: 42.8% | H19: Revenue − Gross Profit | I19: ⚠ Includes ~$5.2B asset impairment in COGS
A20: TXN | B20: 15640 | C20: 17519 | D20: 6240 | E20: 6491 | F20: 60.1% | G20: 62.9% | H20: Directly stated
A21: Qualcomm | B21: 38962 | C21: 35820 | D21: 17026 | E21: 15807 | F21: 56.3% | G21: 55.9% | H21: Directly stated
A22: NXP | B22: 12613 | C22: 13274 | D22: 5348 | E22: 5708 | F22: 57.6% | G22: 57.0% | H22: Directly stated
A23: TSMC | B23: 90447 | C23: 69508 | D23: 39686 | E23: 31601 | F23: 56.1% | G23: 54.5% | H23: Directly stated (TWD→USD)
A24: Micron | B24: 25111 | C24: 15540 | D24: 19440 | E24: 17446 | F24: 22.6% | G24: -12.3% | H24: Revenue − Gross Profit | I24: ⚠ FY2023 gross loss (memory trough)
A25: STM | B25: 13276 | C25: 17290 | D25: 8351 | E25: 9146 | F25: 37.1% | G25: 47.1% | H25: Directly stated
A26: Infineon | B26: 8390 | C26: 8688 | D26: 5160 | E26: 4691 | F26: 38.5% | G26: 46.0% | H26: EUR values × FX rate [A]
A28: 1C — Working Capital Components (USD M) — Trade items only
A29: Company | B29: AR CY (net) | C29: AR PY (net) | D29: Inventory CY | E29: Inventory PY | F29: AP CY | G29: AP PY
A30: NVIDIA | B30: 17254 | C30: 9999 | D30: 5965 | E30: 5282 | F30: 2667 | G30: 1429
A31: AMD | B31: 4427 | C31: 4133 | D31: 1969 | E31: 2008 | F31: 1518 | G31: 1389
A32: Intel | B32: 5021 | C32: 5308 | D32: 11774 | E32: 11296 | F32: 3968 | G32: 4067
A33: TXN | B33: 1741 | C33: 1921 | D33: 4081 | E33: 3547 | F33: 376 | G33: 404
A34: Qualcomm | B34: 6400 | C34: 5614 | D34: 2327 | E34: 2555 | F34: 4213 | G34: 3742
A35: NXP | B35: 1597 | C35: 1741 | D35: 1736 | E35: 1906 | F35: 980 | G35: 1100
A36: TSMC | B36: 10938 | C36: 8691 | D36: 14063 | E36: 12734 | F36: 5625 | G36: 5096
A37: Micron | B37: 3302 | C37: 2757 | D37: 8622 | E37: 8094 | F37: 2232 | G37: 1682
A38: STM | B38: 2014 | C38: 2600 | D38: 2737 | E38: 3068 | F38: 1300 | G38: 1523
A39: Infineon | B39: 1554 | C39: 1709 | D39: 3279 | E39: 3297 | F39: 966 | G39: 1036
A40: 1D — Balance Sheet Summary & OCF (USD M) [A] = Approximated
A41: Company | B41: Total CA [A] | C41: Cash+ST Inv [A] | D41: Other CA [A] | E41: Total CL [A] | F41: AP | G41: ST Debt [A] | H41: Other CL [A] | I41: OCF
A42: NVIDIA | B42: 52876 | C42: 15063 | D42: 14594 | E42: 18975 | F42: 2667 | G42: 1250 | H42: 15058 | I42: 64089
...

Sheet 2 Average Balances
A1: STEP 2 — AVERAGE BALANCE CALCULATIONS (USD M)
A2: Company | B2: Avg AR | C2: Avg Inventory | D2: Avg AP | E2: Avg COGS | F2: Avg Revenue | G2: Formula AR | H2: Formula Inventory | I2: Formula AP | J2: Formula COGS | K2: Formula Revenue
A3: NVIDIA | B3: =('1 Raw Data'!B30+'1 Raw Data'!C30)/2 | C3: =('1 Raw Data'!D30+'1 Raw Data'!E30)/2 | D3: =('1 Raw Data'!F30+'1 Raw Data'!G30)/2 | E3: =('1 Raw Data'!D17+'1 Raw Data'!E17)/2 | F3: =('1 Raw Data'!B17+'1 Raw Data'!C17)/2 | G3: =FORMULATEXT(B3) | H3: =FORMULATEXT(C3) | I3: =FORMULATEXT(D3) | J3: =FORMULATEXT(E3) | K3: =FORMULATEXT(F3)
A4: AMD | B4: =('1 Raw Data'!B31+'1 Raw Data'!C31)/2 | C4: =('1 Raw Data'!D31+'1 Raw Data'!E31)/2 | D4: =('1 Raw Data'!F31+'1 Raw Data'!G31)/2 | E4: =('1 Raw Data'!D18+'1 Raw Data'!E18)/2 | F4: =('1 Raw Data'!B18+'1 Raw Data'!C18)/2 | G4: =FORMULATEXT(B4) | H4: =FORMULATEXT(C4) | I4: =FORMULATEXT(D4) | J4: =FORMULATEXT(E4) | K4: =FORMULATEXT(F4)
A5: Intel | B5: =('1 Raw Data'!B32+'1 Raw Data'!C32)/2 | C5: =('1 Raw Data'!D32+'1 Raw Data'!E32)/2 | D5: =('1 Raw Data'!F32+'1 Raw Data'!G32)/2 | E5: =('1 Raw Data'!D19+'1 Raw Data'!E19)/2 | F5: =('1 Raw Data'!B19+'1 Raw Data'!C19)/2 | G5: =FORMULATEXT(B5) | H5: =FORMULATEXT(C5) | I5: =FORMULATEXT(D5) | J5: =FORMULATEXT(E5) | K5: =FORMULATEXT(F5)
A6: TXN | B6: =('1 Raw Data'!B33+'1 Raw Data'!C33)/2 | C6: =('1 Raw Data'!D33+'1 Raw Data'!E33)/2 | D6: =('1 Raw Data'!F33+'1 Raw Data'!G33)/2 | E6: =('1 Raw Data'!D20+'1 Raw Data'!E20)/2 | F6: =('1 Raw Data'!B20+'1 Raw Data'!C20)/2 | G6: =FORMULATEXT(B6) | H6: =FORMULATEXT(C6) | I6: =FORMULATEXT(D6) | J6: =FORMULATEXT(E6) | K6: =FORMULATEXT(F6)
A7: Qualcomm | B7: =('1 Raw Data'!B34+'1 Raw Data'!C34)/2 | C7: =('1 Raw Data'!D34+'1 Raw Data'!E34)/2 | D7: =('1 Raw Data'!F34+'1 Raw Data'!G34)/2 | E7: =('1 Raw Data'!D21+'1 Raw Data'!E21)/2 | F7: =('1 Raw Data'!B21+'1 Raw Data'!C21)/2 | G7: =FORMULATEXT(B7) | H7: =FORMULATEXT(C7) | I7: =FORMULATEXT(D7) | J7: =FORMULATEXT(E7) | K7: =FORMULATEXT(F7)
A8: NXP | B8: =('1 Raw Data'!B35+'1 Raw Data'!C35)/2 | C8: =('1 Raw Data'!D35+'1 Raw Data'!E35)/2 | D8: =('1 Raw Data'!F35+'1 Raw Data'!G35)/2 | E8: =('1 Raw Data'!D22+'1 Raw Data'!E22)/2 | F8: =('1 Raw Data'!B22+'1 Raw Data'!C22)/2 | G8: =FORMULATEXT(B8) | H8: =FORMULATEXT(C8) | I8: =FORMULATEXT(D8) | J8: =FORMULATEXT(E8) | K8: =FORMULATEXT(F8)
A9: TSMC | B9: =('1 Raw Data'!B36+'1 Raw Data'!C36)/2 | C9: =('1 Raw Data'!D36+'1 Raw Data'!E36)/2 | D9: =('1 Raw Data'!F36+'1 Raw Data'!G36)/2 | E9: =('1 Raw Data'!D23+'1 Raw Data'!E23)/2 | F9: =('1 Raw Data'!B23+'1 Raw Data'!C23)/2 | G9: =FORMULATEXT(B9) | H9: =FORMULATEXT(C9) | I9: =FORMULATEXT(D9) | J9: =FORMULATEXT(E9) | K9: =FORMULATEXT(F9)
A10: Micron | B10: =('1 Raw Data'!B37+'1 Raw Data'!C37)/2 | C10: =('1 Raw Data'!D37+'1 Raw Data'!E37)/2 | D10: =('1 Raw Data'!F37+'1 Raw Data'!G37)/2 | E10: =('1 Raw Data'!D24+'1 Raw Data'!E24)/2 | F10: =('1 Raw Data'!B24+'1 Raw Data'!C24)/2 | G10: =FORMULATEXT(B10) | H10: =FORMULATEXT(C10) | I10: =FORMULATEXT(D10) | J10: =FORMULATEXT(E10) | K10: =FORMULATEXT(F10)
A11: STM | B11: =('1 Raw Data'!B38+'1 Raw Data'!C38)/2 | C11: =('1 Raw Data'!D38+'1 Raw Data'!E38)/2 | D11: =('1 Raw Data'!F38+'1 Raw Data'!G38)/2 | E11: =('1 Raw Data'!D25+'1 Raw Data'!E25)/2 | F11: =('1 Raw Data'!B25+'1 Raw Data'!C25)/2 | G11: =FORMULATEXT(B11) | H11: =FORMULATEXT(C11) | I11: =FORMULATEXT(D11) | J11: =FORMULATEXT(E11) | K11: =FORMULATEXT(F11)
A12: Infineon | B12: =('1 Raw Data'!B39+'1 Raw Data'!C39)/2 | C12: =('1 Raw Data'!D39+'1 Raw Data'!E39)/2 | D12: =('1 Raw Data'!F39+'1 Raw Data'!G39)/2 | E12: =('1 Raw Data'!D26+'1 Raw Data'!E26)/2 | F12: =('1 Raw Data'!B26+'1 Raw Data'!C26)/2 | G12: =FORMULATEXT(B12) | H12: =FORMULATEXT(C12) | I12: =FORMULATEXT(D12) | J12: =FORMULATEXT(E12) | K12: =FORMULATEXT(F12)

Sheet 3 Metrics
A1: STEP 3 — METRIC CALCULATIONS (all ratios rounded to 2 dp)
A2: Company | B2: WC (USD M) | C2: BS NWC (USD M) | D2: Op. NWC (USD M) | E2: NWC% (%) | F2: WC Intensity | G2: Current Ratio | H2: DSO (days) | I2: AR Turns (×) | J2: DIO (days) | K2: DPO (days) | L2: CCC (days) | M2: CRR (%) | N2: Note
A3: NVIDIA | B3: ='1 Raw Data'!B42-'1 Raw Data'!E42 | C3: ='1 Raw Data'!B42-'1 Raw Data'!C42-'1 Raw Data'!E42+'1 Raw Data'!G42 | D3: ='2 Average Balances'!B3+'2 Average Balances'!C3-'2 Average Balances'!D3 | E3: =D3/('1 Raw Data'!B17)*100 | F3: =B3/('1 Raw Data'!B17) | G3: ='1 Raw Data'!B42/'1 Raw Data'!E42 | H3: ='2 Average Balances'!B3/('1 Raw Data'!B17/365) | I3: ='1 Raw Data'!B17/'2 Average Balances'!B3 | J3: ='2 Average Balances'!C3/('2 Average Balances'!E3/365) | K3: ='2 Average Balances'!D3/('2 Average Balances'!E3/365) | L3: =H3+J3-K3 | M3: ='1 Raw Data'!I42/('1 Raw Data'!B17)*100
A4: AMD | B4: ='1 Raw Data'!B43-'1 Raw Data'!E43 | C4: ='1 Raw Data'!B43-'1 Raw Data'!C43-'1 Raw Data'!E43+'1 Raw Data'!G43 | D4: ='2 Average Balances'!B4+'2 Average Balances'!C4-'2 Average Balances'!D4 | E4: =D4/('1 Raw Data'!B18)*100 | F4: =B4/('1 Raw Data'!B18) | G4: ='1 Raw Data'!B43/'1 Raw Data'!E43 | H4: ='2 Average Balances'!B4/('1 Raw Data'!B18/365) | I4: ='1 Raw Data'!B18/'2 Average Balances'!B4 | J4: ='2 Average Balances'!C4/('2 Average Balances'!E4/365) | K4: ='2 Average Balances'!D4/('2 Average Balances'!E4/365) | L4: =H4+J4-K4 | M4: ='1 Raw Data'!I43/('1 Raw Data'!B18)*100
A5: Intel | B5: ='1 Raw Data'!B44-'1 Raw Data'!E44 | C5: ='1 Raw Data'!B44-'1 Raw Data'!C44-'1 Raw Data'!E44+'1 Raw Data'!G44 | D5: ='2 Average Balances'!B5+'2 Average Balances'!C5-'2 Average Balances'!D5 | E5: =D5/('1 Raw Data'!B19)*100 | F5: =B5/('1 Raw Data'!B19) | G5: ='1 Raw Data'!B44/'1 Raw Data'!E44 | H5: ='2 Average Balances'!B5/('1 Raw Data'!B19/365) | I5: ='1 Raw Data'!B19/'2 Average Balances'!B5 | J5: ='2 Average Balances'!C5/('2 Average Balances'!E5/365) | K5: ='2 Average Balances'!D5/('2 Average Balances'!E5/365) | L5: =H5+J5-K5 | M5: ='1 Raw Data'!I44/('1 Raw Data'!B19)*100 | N5: ⚠ COGS incl. impairment
A6: TXN | B6: ='1 Raw Data'!B45-'1 Raw Data'!E45 | C6: ='1 Raw Data'!B45-'1 Raw Data'!C45-'1 Raw Data'!E45+'1 Raw Data'!G45 | D6: ='2 Average Balances'!B6+'2 Average Balances'!C6-'2 Average Balances'!D6 | E6: =D6/('1 Raw Data'!B20)*100 | F6: =B6/('1 Raw Data'!B20) | G6: ='1 Raw Data'!B45/'1 Raw Data'!E45 | H6: ='2 Average Balances'!B6/('1 Raw Data'!B20/365) | I6: ='1 Raw Data'!B20/'2 Average Balances'!B6 | J6: ='2 Average Balances'!C6/('2 Average Balances'!E6/365) | K6: ='2 Average Balances'!D6/('2 Average Balances'!E6/365) | L6: =H6+J6-K6 | M6: ='1 Raw Data'!I45/('1 Raw Data'!B20)*100 | N6: ⚠ Strategic inventory build
A7: Qualcomm | B7: ='1 Raw Data'!B46-'1 Raw Data'!E46 | C7: ='1 Raw Data'!B46-'1 Raw Data'!C46-'1 Raw Data'!E46+'1 Raw Data'!G46 | D7: ='2 Average Balances'!B7+'2 Average Balances'!C7-'2 Average Balances'!D7 | E7: =D7/('1 Raw Data'!B21)*100 | F7: =B7/('1 Raw Data'!B21) | G7: ='1 Raw Data'!B46/'1 Raw Data'!E46 | H7: ='2 Average Balances'!B7/('1 Raw Data'!B21/365) | I7: ='1 Raw Data'!B21/'2 Average Balances'!B7 | J7: ='2 Average Balances'!C7/('2 Average Balances'!E7/365) | K7: ='2 Average Balances'!D7/('2 Average Balances'!E7/365) | L7: =H7+J7-K7 | M7: ='1 Raw Data'!I46/('1 Raw Data'!B21)*100
A8: NXP | B8: ='1 Raw Data'!B47-'1 Raw Data'!E47 | C8: ='1 Raw Data'!B47-'1 Raw Data'!C47-'1 Raw Data'!E47+'1 Raw Data'!G47 | D8: ='2 Average Balances'!B8+'2 Average Balances'!C8-'2 Average Balances'!D8 | E8: =D8/('1 Raw Data'!B22)*100 | F8: =B8/('1 Raw Data'!B22) | G8: ='1 Raw Data'!B47/'1 Raw Data'!E47 | H8: ='2 Average Balances'!B8/('1 Raw Data'!B22/365) | I8: ='1 Raw Data'!B22/'2 Average Balances'!B8 | J8: ='2 Average Balances'!C8/('2 Average Balances'!E8/365) | K8: ='2 Average Balances'!D8/('2 Average Balances'!E8/365) | L8: =H8+J8-K8 | M8: ='1 Raw Data'!I47/('1 Raw Data'!B22)*100
A9: TSMC | B9: ='1 Raw Data'!B48-'1 Raw Data'!E48 | C9: ='1 Raw Data'!B48-'1 Raw Data'!C48-'1 Raw Data'!E48+'1 Raw Data'!G48 | D9: ='2 Average Balances'!B9+'2 Average Balances'!C9-'2 Average Balances'!D9 | E9: =D9/('1 Raw Data'!B23)*100 | F9: =B9/('1 Raw Data'!B23) | G9: ='1 Raw Data'!B48/'1 Raw Data'!E48 | H9: ='2 Average Balances'!B9/('1 Raw Data'!B23/365) | I9: ='1 Raw Data'!B23/'2 Average Balances'!B9 | J9: ='2 Average Balances'!C9/('2 Average Balances'!E9/365) | K9: ='2 Average Balances'!D9/('2 Average Balances'!E9/365) | L9: =H9+J9-K9 | M9: ='1 Raw Data'!I48/('1 Raw Data'!B23)*100 | N9: [A] OCF estimated
A10: Micron | B10: ='1 Raw Data'!B49-'1 Raw Data'!E49 | C10: ='1 Raw Data'!B49-'1 Raw Data'!C49-'1 Raw Data'!E49+'1 Raw Data'!G49 | D10: ='2 Average Balances'!B10+'2 Average Balances'!C10-'2 Average Balances'!D10 | E10: =D10/('1 Raw Data'!B24)*100 | F10: =B10/('1 Raw Data'!B24) | G10: ='1 Raw Data'!B49/'1 Raw Data'!E49 | H10: ='2 Average Balances'!B10/('1 Raw Data'!B24/365) | I10: ='1 Raw Data'!B24/'2 Average Balances'!B10 | J10: ='2 Average Balances'!C10/('2 Average Balances'!E10/365) | K10: ='2 Average Balances'!D10/('2 Average Balances'!E10/365) | L10: =H10+J10-K10 | M10: ='1 Raw Data'!I49/('1 Raw Data'!B24)*100 | N10: ⚠ Memory cycle distortion
A11: STM | B11: ='1 Raw Data'!B50-'1 Raw Data'!E50 | C11: ='1 Raw Data'!B50-'1 Raw Data'!C50-'1 Raw Data'!E50+'1 Raw Data'!G50 | D11: ='2 Average Balances'!B11+'2 Average Balances'!C11-'2 Average Balances'!D11 | E11: =D11/('1 Raw Data'!B25)*100 | F11: =B11/('1 Raw Data'!B25) | G11: ='1 Raw Data'!B50/'1 Raw Data'!E50 | H11: ='2 Average Balances'!B11/('1 Raw Data'!B25/365) | I11: ='1 Raw Data'!B25/'2 Average Balances'!B11 | J11: ='2 Average Balances'!C11/('2 Average Balances'!E11/365) | K11: ='2 Average Balances'!D11/('2 Average Balances'!E11/365) | L11: =H11+J11-K11 | M11: ='1 Raw Data'!I50/('1 Raw Data'!B25)*100
A12: Infineon | B12: ='1 Raw Data'!B51-'1 Raw Data'!E51 | C12: ='1 Raw Data'!B51-'1 Raw Data'!C51-'1 Raw Data'!E51+'1 Raw Data'!G51 | D12: ='2 Average Balances'!B12+'2 Average Balances'!C12-'2 Average Balances'!D12 | E12: =D12/('1 Raw Data'!B26)*100 | F12: =B12/('1 Raw Data'!B26) | G12: ='1 Raw Data'!B51/'1 Raw Data'!E51 | H12: ='2 Average Balances'!B12/('1 Raw Data'!B26/365) | I12: ='1 Raw Data'!B26/'2 Average Balances'!B12 | J12: ='2 Average Balances'!C12/('2 Average Balances'!E12/365) | K12: ='2 Average Balances'!D12/('2 Average Balances'!E12/365) | L12: =H12+J12-K12 | M12: ='1 Raw Data'!I51/('1 Raw Data'!B26)*100 | N12: ⚠ Auto inventory crisis

Sheet 4 Rankings
A1: STEP 4 — RANKING TABLE (1 = Best in peer group)
A2: Company | B2: DSO Rank↓ | C2: AR Turns Rank↑ | D2: DIO Rank↓ | E2: DPO Rank↑ | F2: CCC Rank↓ | G2: CRR Rank↑ | H2: NWC% Rank↓ | I2: WC Intensity Rank↓ | J2: Current Ratio
A3: NVIDIA | B3: =RANK('3 Metrics'!H3,'3 Metrics'!$H$3:$H$12,1) | C3: =RANK('3 Metrics'!I3,'3 Metrics'!$I$3:$I$12,0) | D3: =RANK('3 Metrics'!J3,'3 Metrics'!$J$3:$J$12,1) | E3: =RANK('3 Metrics'!K3,'3 Metrics'!$K$3:$K$12,0) | F3: =RANK('3 Metrics'!L3,'3 Metrics'!$L$3:$L$12,1) | G3: =RANK('3 Metrics'!M3,'3 Metrics'!$M$3:$M$12,0) | H3: =RANK('3 Metrics'!E3,'3 Metrics'!$E$3:$E$12,1) | I3: =RANK('3 Metrics'!F3,'3 Metrics'!$F$3:$F$12,1) | J3: 2.79 – Cash-rich, no concern
A4: AMD | B4: =RANK('3 Metrics'!H4,'3 Metrics'!$H$3:$H$12,1) | C4: =RANK('3 Metrics'!I4,'3 Metrics'!$I$3:$I$12,0) | D4: =RANK('3 Metrics'!J4,'3 Metrics'!$J$3:$J$12,1) | E4: =RANK('3 Metrics'!K4,'3 Metrics'!$K$3:$K$12,0) | F4: =RANK('3 Metrics'!L4,'3 Metrics'!$L$3:$L$12,1) | G4: =RANK('3 Metrics'!M4,'3 Metrics'!$M$3:$M$12,0) | H4: =RANK('3 Metrics'!E4,'3 Metrics'!$E$3:$E$12,1) | I4: =RANK('3 Metrics'!F4,'3 Metrics'!$F$3:$F$12,1) | J4: 2.74 – Healthy fabless
A5: Intel | B5: =RANK('3 Metrics'!H5,'3 Metrics'!$H$3:$H$12,1) | C5: =RANK('3 Metrics'!I5,'3 Metrics'!$I$3:$I$12,0) | D5: =RANK('3 Metrics'!J5,'3 Metrics'!$J$3:$J$12,1) | E5: =RANK('3 Metrics'!K5,'3 Metrics'!$K$3:$K$12,0) | F5: =RANK('3 Metrics'!L5,'3 Metrics'!$L$3:$L$12,1) | G5: =RANK('3 Metrics'!M5,'3 Metrics'!$M$3:$M$12,0) | H5: =RANK('3 Metrics'!E5,'3 Metrics'!$E$3:$E$12,1) | I5: =RANK('3 Metrics'!F5,'3 Metrics'!$F$3:$F$12,1) | J5: 1.33 – Low; restructuring payables
A6: TXN | B6: =RANK('3 Metrics'!H6,'3 Metrics'!$H$3:$H$12,1) | C6: =RANK('3 Metrics'!I6,'3 Metrics'!$I$3:$I$12,0) | D6: =RANK('3 Metrics'!J6,'3 Metrics'!$J$3:$J$12,1) | E6: =RANK('3 Metrics'!K6,'3 Metrics'!$K$3:$K$12,0) | F6: =RANK('3 Metrics'!L6,'3 Metrics'!$L$3:$L$12,1) | G6: =RANK('3 Metrics'!M6,'3 Metrics'!$M$3:$M$12,0) | H6: =RANK('3 Metrics'!E6,'3 Metrics'!$E$3:$E$12,1) | I6: =RANK('3 Metrics'!F6,'3 Metrics'!$F$3:$F$12,1) | J6: 2.55 – Good; DIO is strategic
A7: Qualcomm | B7: =RANK('3 Metrics'!H7,'3 Metrics'!$H$3:$H$12,1) | C7: =RANK('3 Metrics'!I7,'3 Metrics'!$I$3:$I$12,0) | D7: =RANK('3 Metrics'!J7,'3 Metrics'!$J$3:$J$12,1) | E7: =RANK('3 Metrics'!K7,'3 Metrics'!$K$3:$K$12,0) | F7: =RANK('3 Metrics'!L7,'3 Metrics'!$L$3:$L$12,1) | G7: =RANK('3 Metrics'!M7,'3 Metrics'!$M$3:$M$12,0) | H7: =RANK('3 Metrics'!E7,'3 Metrics'!$E$3:$E$12,1) | I7: =RANK('3 Metrics'!F7,'3 Metrics'!$F$3:$F$12,1) | J7: 1.93 – Solid fabless
A8: NXP | B8: =RANK('3 Metrics'!H8,'3 Metrics'!$H$3:$H$12,1) | C8: =RANK('3 Metrics'!I8,'3 Metrics'!$I$3:$I$12,0) | D8: =RANK('3 Metrics'!J8,'3 Metrics'!$J$3:$J$12,1) | E8: =RANK('3 Metrics'!K8,'3 Metrics'!$K$3:$K$12,0) | F8: =RANK('3 Metrics'!L8,'3 Metrics'!$L$3:$L$12,1) | G8: =RANK('3 Metrics'!M8,'3 Metrics'!$M$3:$M$12,0) | H8: =RANK('3 Metrics'!E8,'3 Metrics'!$E$3:$E$12,1) | I8: =RANK('3 Metrics'!F8,'3 Metrics'!$F$3:$F$12,1) | J8: 1.55 – Adequate
A9: TSMC | B9: =RANK('3 Metrics'!H9,'3 Metrics'!$H$3:$H$12,1) | C9: =RANK('3 Metrics'!I9,'3 Metrics'!$I$3:$I$12,0) | D9: =RANK('3 Metrics'!J9,'3 Metrics'!$J$3:$J$12,1) | E9: =RANK('3 Metrics'!K9,'3 Metrics'!$K$3:$K$12,0) | F9: =RANK('3 Metrics'!L9,'3 Metrics'!$L$3:$L$12,1) | G9: =RANK('3 Metrics'!M9,'3 Metrics'!$M$3:$M$12,0) | H9: =RANK('3 Metrics'!E9,'3 Metrics'!$E$3:$E$12,1) | I9: =RANK('3 Metrics'!F9,'3 Metrics'!$F$3:$F$12,1) | J9: 2.76 – High; capex cash reserves
A10: Micron | B10: =RANK('3 Metrics'!H10,'3 Metrics'!$H$3:$H$12,1) | C10: =RANK('3 Metrics'!I10,'3 Metrics'!$I$3:$I$12,0) | D10: =RANK('3 Metrics'!J10,'3 Metrics'!$J$3:$J$12,1) | E10: =RANK('3 Metrics'!K10,'3 Metrics'!$K$3:$K$12,0) | F10: =RANK('3 Metrics'!L10,'3 Metrics'!$L$3:$L$12,1) | G10: =RANK('3 Metrics'!M10,'3 Metrics'!$M$3:$M$12,0) | H10: =RANK('3 Metrics'!E10,'3 Metrics'!$E$3:$E$12,1) | I10: =RANK('3 Metrics'!F10,'3 Metrics'!$F$3:$F$12,1) | J10: 2.52 – Adequate; memory recovery
A11: STM | B11: =RANK('3 Metrics'!H11,'3 Metrics'!$H$3:$H$12,1) | C11: =RANK('3 Metrics'!I11,'3 Metrics'!$I$3:$I$12,0) | D11: =RANK('3 Metrics'!J11,'3 Metrics'!$J$3:$J$12,1) | E11: =RANK('3 Metrics'!K11,'3 Metrics'!$K$3:$K$12,0) | F11: =RANK('3 Metrics'!L11,'3 Metrics'!$L$3:$L$12,1) | G11: =RANK('3 Metrics'!M11,'3 Metrics'!$M$3:$M$12,0) | H11: =RANK('3 Metrics'!E11,'3 Metrics'!$E$3:$E$12,1) | I11: =RANK('3 Metrics'!F11,'3 Metrics'!$F$3:$F$12,1) | J11: 2.13 – Adequate
A12: Infineon | B12: =RANK('3 Metrics'!H12,'3 Metrics'!$H$3:$H$12,1) | C12: =RANK('3 Metrics'!I12,'3 Metrics'!$I$3:$I$12,0) | D12: =RANK('3 Metrics'!J12,'3 Metrics'!$J$3:$J$12,1) | E12: =RANK('3 Metrics'!K12,'3 Metrics'!$K$3:$K$12,0) | F12: =RANK('3 Metrics'!L12,'3 Metrics'!$L$3:$L$12,1) | G12: =RANK('3 Metrics'!M12,'3 Metrics'!$M$3:$M$12,0) | H12: =RANK('3 Metrics'!E12,'3 Metrics'!$E$3:$E$12,1) | I12: =RANK('3 Metrics'!F12,'3 Metrics'!$F$3:$F$12,1) | J12: 1.74 – Adequate; auto distress

Sheet 5 Scoring Model
A1: STEP 5 — SCORING MODEL
A2: Version A: Equal Weights 20% each | Version B: CCC 30%, NWC% 25%, DSO 15%, AR Turns 15%, CRR 15%
A3: Company | B3: DSO Rank | C3: AR Turns Rank | D3: CCC Rank | E3: CRR Rank | F3: NWC% Rank | G3: V-A Score (eq. wt) | H3: V-A Rank | I3: V-B Score (sens. wt) | J3: V-B Rank | K3: Quartile | L3: Best-Practice? | M3: Rank-shift A→B
A4: NVIDIA | B4: ='4 Rankings'!B3 | C4: ='4 Rankings'!C3 | D4: ='4 Rankings'!F3 | E4: ='4 Rankings'!G3 | F4: ='4 Rankings'!H3 | G4: =(B4+C4+D4+E4+F4)/5 | H4: =RANK(G4,$G$4:$G$13,1) | I4: =D4*0.30+F4*0.25+B4*0.15+C4*0.15+E4*0.15 | J4: =RANK(I4,$I$4:$I$13,1) | K4: =IF(H4<=3,"Q1",IF(H4<=5,"Q2",IF(H4<=8,"Q3","Q4"))) | L4: 🏆 Overall Best | M4: =IF(H4-J4=0,"Stable",IF(H4-J4>0,"+"&(H4-J4)&" (V-B)",(H4-J4)&" (V-B)"))
A5: AMD | B5: ='4 Rankings'!B4 | C5: ='4 Rankings'!C4 | D5: ='4 Rankings'!F4 | E5: ='4 Rankings'!G4 | F5: ='4 Rankings'!H4 | G5: =(B5+C5+D5+E5+F5)/5 | H5: =RANK(G5,$G$4:$G$13,1) | I5: =D5*0.30+F5*0.25+B5*0.15+C5*0.15+E5*0.15 | J5: =RANK(I5,$I$4:$I$13,1) | K5: =IF(H5<=3,"Q1",IF(H5<=5,"Q2",IF(H5<=8,"Q3","Q4"))) | M5: =IF(H5-J5=0,"Stable",IF(H5-J5>0,"+"&(H5-J5)&" (V-B)",(H5-J5)&" (V-B)"))
A6: Intel | B6: ='4 Rankings'!B5 | C6: ='4 Rankings'!C5 | D6: ='4 Rankings'!F5 | E6: ='4 Rankings'!G5 | F6: ='4 Rankings'!H5 | G6: =(B6+C6+D6+E6+F6)/5 | H6: =RANK(G6,$G$4:$G$13,1) | I6: =D6*0.30+F6*0.25+B6*0.15+C6*0.15+E6*0.15 | J6: =RANK(I6,$I$4:$I$13,1) | K6: =IF(H6<=3,"Q1",IF(H6<=5,"Q2",IF(H6<=8,"Q3","Q4"))) | M6: =IF(H6-J6=0,"Stable",IF(H6-J6>0,"+"&(H6-J6)&" (V-B)",(H6-J6)&" (V-B)"))
A7: TXN | B7: ='4 Rankings'!B6 | C7: ='4 Rankings'!C6 | D7: ='4 Rankings'!F6 | E7: ='4 Rankings'!G6 | F7: ='4 Rankings'!H6 | G7: =(B7+C7+D7+E7+F7)/5 | H7: =RANK(G7,$G$4:$G$13,1) | I7: =D7*0.30+F7*0.25+B7*0.15+C7*0.15+E7*0.15 | J7: =RANK(I7,$I$4:$I$13,1) | K7: =IF(H7<=3,"Q1",IF(H7<=5,"Q2",IF(H7<=8,"Q3","Q4"))) | M7: =IF(H7-J7=0,"Stable",IF(H7-J7>0,"+"&(H7-J7)&" (V-B)",(H7-J7)&" (V-B)"))
A8: Qualcomm | B8: ='4 Rankings'!B7 | C8: ='4 Rankings'!C7 | D8: ='4 Rankings'!F7 | E8: ='4 Rankings'!G7 | F8: ='4 Rankings'!H7 | G8: =(B8+C8+D8+E8+F8)/5 | H8: =RANK(G8,$G$4:$G$13,1) | I8: =D8*0.30+F8*0.25+B8*0.15+C8*0.15+E8*0.15 | J8: =RANK(I8,$I$4:$I$13,1) | K8: =IF(H8<=3,"Q1",IF(H8<=5,"Q2",IF(H8<=8,"Q3","Q4"))) | L8: Best CCC & NWC% | M8: =IF(H8-J8=0,"Stable",IF(H8-J8>0,"+"&(H8-J8)&" (V-B)",(H8-J8)&" (V-B)"))
A9: NXP | B9: ='4 Rankings'!B8 | C9: ='4 Rankings'!C8 | D9: ='4 Rankings'!F8 | E9: ='4 Rankings'!G8 | F9: ='4 Rankings'!H8 | G9: =(B9+C9+D9+E9+F9)/5 | H9: =RANK(G9,$G$4:$G$13,1) | I9: =D9*0.30+F9*0.25+B9*0.15+C9*0.15+E9*0.15 | J9: =RANK(I9,$I$4:$I$13,1) | K9: =IF(H9<=3,"Q1",IF(H9<=5,"Q2",IF(H9<=8,"Q3","Q4"))) | M9: =IF(H9-J9=0,"Stable",IF(H9-J9>0,"+"&(H9-J9)&" (V-B)",(H9-J9)&" (V-B)"))
A10: TSMC | B10: ='4 Rankings'!B9 | C10: ='4 Rankings'!C9 | D10: ='4 Rankings'!F9 | E10: ='4 Rankings'!G9 | F10: ='4 Rankings'!H9 | G10: =(B10+C10+D10+E10+F10)/5 | H10: =RANK(G10,$G$4:$G$13,1) | I10: =D10*0.30+F10*0.25+B10*0.15+C10*0.15+E10*0.15 | J10: =RANK(I10,$I$4:$I$13,1) | K10: =IF(H10<=3,"Q1",IF(H10<=5,"Q2",IF(H10<=8,"Q3","Q4"))) | L10: Best CRR | M10: =IF(H10-J10=0,"Stable",IF(H10-J10>0,"+"&(H10-J10)&" (V-B)",(H10-J10)&" (V-B)"))
A11: Micron | B11: ='4 Rankings'!B10 | C11: ='4 Rankings'!C10 | D11: ='4 Rankings'!F10 | E11: ='4 Rankings'!G10 | F11: ='4 Rankings'!H10 | G11: =(B11+C11+D11+E11+F11)/5 | H11: =RANK(G11,$G$4:$G$13,1) | I11: =D11*0.30+F11*0.25+B11*0.15+C11*0.15+E11*0.15 | J11: =RANK(I11,$I$4:$I$13,1) | K11: =IF(H11<=3,"Q1",IF(H11<=5,"Q2",IF(H11<=8,"Q3","Q4"))) | M11: =IF(H11-J11=0,"Stable",IF(H11-J11>0,"+"&(H11-J11)&" (V-B)",(H11-J11)&" (V-B)"))
A12: STM | B12: ='4 Rankings'!B11 | C12: ='4 Rankings'!C11 | D12: ='4 Rankings'!F11 | E12: ='4 Rankings'!G11 | F12: ='4 Rankings'!H11 | G12: =(B12+C12+D12+E12+F12)/5 | H12: =RANK(G12,$G$4:$G$13,1) | I12: =D12*0.30+F12*0.25+B12*0.15+C12*0.15+E12*0.15 | J12: =RANK(I12,$I$4:$I$13,1) | K12: =IF(H12<=3,"Q1",IF(H12<=5,"Q2",IF(H12<=8,"Q3","Q4"))) | M12: =IF(H12-J12=0,"Stable",IF(H12-J12>0,"+"&(H12-J12)&" (V-B)",(H12-J12)&" (V-B)"))
A13: Infineon | B13: ='4 Rankings'!B12 | C13: ='4 Rankings'!C12 | D13: ='4 Rankings'!F12 | E13: ='4 Rankings'!G12 | F13: ='4 Rankings'!H12 | G13: =(B13+C13+D13+E13+F13)/5 | H13: =RANK(G13,$G$4:$G$13,1) | I13: =D13*0.30+F13*0.25+B13*0.15+C13*0.15+E13*0.15 | J13: =RANK(I13,$I$4:$I$13,1) | K13: =IF(H13<=3,"Q1",IF(H13<=5,"Q2",IF(H13<=8,"Q3","Q4"))) | M13: =IF(H13-J13=0,"Stable",IF(H13-J13>0,"+"&(H13-J13)&" (V-B)",(H13-J13)&" (V-B)"))

Sheet 6 Cash Potential
A1: STEP 6 — CASH POTENTIAL (Q3 & Q4 companies only, USD M)
A2: ="Best-in-Class: DSO = "&INDEX('3 Metrics'!$A$3:$A$12,MATCH(MIN('3 Metrics'!$H$3:$H$12),'3 Metrics'!$H$3:$H$12,0))&" "&TEXT(MIN('3 Metrics'!$H$3:$H$12),"0.00")&"d | DIO = "&INDEX('3 Metrics'!$A$3:$A$12,MATCH(MIN('3 Metrics'!$J$3:$J$12),'3 Metrics'!$J$3:$J$12,0))&" "&TEXT(MIN('3 Metrics'!$J$3:$J$12),"0.00")&"d | DPO = "&INDEX('3 Metrics'!$A$3:$A$12,MATCH(MAX('3 Metrics'!$K$3:$K$12),'3 Metrics'!$K$3:$K$12,0))&" "&TEXT(MAX('3 Metrics'!$K$3:$K$12),"0.00")&"d"
A3: Company | B3: Quartile | C3: DSO Lever (USD M) | D3: DSO Gap (days) | E3: DIO Lever (USD M) | F3: DIO Gap (days) | G3: DPO Lever (USD M) | H3: DPO Gap (days) | I3: TOTAL Cash Potential (USD M)
A4: TXN | B4: ='5 Scoring Model'!K7 | C4: =D4*('1 Raw Data'!B20/365) | D4: ='3 Metrics'!H6-MIN('3 Metrics'!$H$3:$H$12) | E4: =F4*('2 Average Balances'!E6/365) | F4: ='3 Metrics'!J6-MIN('3 Metrics'!$J$3:$J$12) | G4: =H4*('2 Average Balances'!E6/365) | H4: =MAX('3 Metrics'!$K$3:$K$12)-'3 Metrics'!K6 | I4: =C4+E4+G4
A5: AMD | B5: ='5 Scoring Model'!K5 | C5: =D5*('1 Raw Data'!B18/365) | D5: ='3 Metrics'!H4-MIN('3 Metrics'!$H$3:$H$12) | E5: =F5*('2 Average Balances'!E4/365) | F5: ='3 Metrics'!J4-MIN('3 Metrics'!$J$3:$J$12) | G5: =H5*('2 Average Balances'!E4/365) | H5: =MAX('3 Metrics'!$K$3:$K$12)-'3 Metrics'!K4 | I5: =C5+E5+G5
A6: Micron | B6: ='5 Scoring Model'!K11 | C6: =D6*('1 Raw Data'!B24/365) | D6: ='3 Metrics'!H10-MIN('3 Metrics'!$H$3:$H$12) | E6: =F6*('2 Average Balances'!E10/365) | F6: ='3 Metrics'!J10-MIN('3 Metrics'!$J$3:$J$12) | G6: =H6*('2 Average Balances'!E10/365) | H6: =MAX('3 Metrics'!$K$3:$K$12)-'3 Metrics'!K10 | I6: =C6+E6+G6
A7: STM | B7: ='5 Scoring Model'!K12 | C7: =D7*('1 Raw Data'!B25/365) | D7: ='3 Metrics'!H11-MIN('3 Metrics'!$H$3:$H$12) | E7: =F7*('2 Average Balances'!E11/365) | F7: ='3 Metrics'!J11-MIN('3 Metrics'!$J$3:$J$12) | G7: =H7*('2 Average Balances'!E11/365) | H7: =MAX('3 Metrics'!$K$3:$K$12)-'3 Metrics'!K11 | I7: =C7+E7+G7
A8: Infineon | B8: ='5 Scoring Model'!K13 | C8: =D8*('1 Raw Data'!B26/365) | D8: ='3 Metrics'!H12-MIN('3 Metrics'!$H$3:$H$12) | E8: =F8*('2 Average Balances'!E12/365) | F8: ='3 Metrics'!J12-MIN('3 Metrics'!$J$3:$J$12) | G8: =H8*('2 Average Balances'!E12/365) | H8: =MAX('3 Metrics'!$K$3:$K$12)-'3 Metrics'!K12 | I8: =C8+E8+G8
A10: ⚠ NOTE: Cash release is realistically achievable over 12–24 months, subject to execution constraints. Micron's DIO improvement is partially market-dependent (memory cycle).

Sheet 7 NWC Strategy
A1: STEP 7 — NWC OPTIMIZATION STRATEGY (Q3 & Q4 companies)
A2: Company | B2: Quartile | C2: Primary Problem | D2: Gap vs. Best-in-Class | E2: Secondary Problem | F2: Benchmark Peer | G2: Recommended Actions (3)
A3: TXN | B3: Q3 | C3: DIO = 218.70d (⚠ strategic build) | D3: DIO gap vs. Qualcomm: 164.42 days → $2,867M trapped | E3: DPO = 22.37d (lowest in group) | F3: Qualcomm (DIO & DPO) | G3: 1) Structured inventory normalisation over 4–6Q, shift to build-to-order for low-velocity SKUs 2) Negotiate extended supplier payment terms to 45–60d via reverse-factoring (Taulia/C2FO) 3) VMI/consignment programmes with Arrow & Avnet to shift buffer inventory off-balance-sheet
A4: AMD | B4: Q3 | C4: DSO = 60.59d | D4: DSO gap vs. Intel: 25.09 days → $1,773M trapped | E4: DPO = 44.29d | F4: Intel (DSO); Qualcomm (DPO) | G4: 1) Tighten distribution credit terms; enforce net-30/45 max; accelerate invoicing on shipment 2) Deploy reverse-factoring for TSMC/OSAT suppliers to extend DPO from ~44d to 65–70d 3) Benchmark AR ageing vs. Intel; implement e-invoicing + automated dunning platform
A5: Micron | B5: Q3 | C5: DIO = 165.43d (⚠ memory cycle) | D5: DIO gap vs. Qualcomm: 111.15 days → $5,615M (vs. IDM peer NXP: 45d → $2,284M) | E5: DPO = 38.73d (lowest IDM) | F5: NXP/STM (DIO – IDM peers); Qualcomm (cap rule per methodology) | G5: 1) Align bit-production caps to DRAM/NAND spot-price indices + customer PO visibility 2) Long-term supply agreements with hyperscalers (AWS, Google, Microsoft) for HBM3/DDR5 3) Leverage capex scale ($8–12B/yr) to extend supplier payment terms from ~39d to 55–65d
A6: STM | B6: Q4 | C6: DSO = 63.43d | D6: DSO gap vs. Intel: 27.93 days → $1,016M | E6: DIO = 121.10d | F6: NXP (overall NWC); Intel (DSO target) | G6: 1) Implement AR factoring / SCF for European automotive OEM receivables (BNP Paribas/Santander) 2) SKU rationalisation + consignment programmes with Mouser/Digi-Key for legacy inventory 3) Early-payment incentive (1–2% discount for <15d payment) for Tier-1 automotive customers
A7: Infineon | B7: Q4 | C7: DIO = 243.74d (⚠ auto inventory crisis) | D7: DIO gap vs. Qualcomm: 189.46 days → $2,557M; target 140–160d within 18 months | E7: DSO = 70.97d (highest in group) | F7: NXP (overall); Intel (DSO target ~50–55d realistic) | G7: 1) Fab utilisation throttling for IGBT/SiC; demand-pull model; accept short-term underabsorption 2) VMI/consignment with Bosch, Continental, ZF for automotive programme inventory 3) Pan-European reverse-factoring platform for 200+ suppliers; extend DPO from 74d to 85–90d

Sheet 8 Business Model
A1: STEP 8 — BUSINESS MODEL COMMENTARY
A2: 8.1 — Fabless vs. Foundry vs. IDM
A3: Fabless (NVIDIA, AMD, Qualcomm)
A4: • No manufacturing assets. Production outsourced to TSMC/Samsung/GlobalFoundries.
A5: • Inventory = finished goods only (at 3PL). No raw materials or WIP at own facilities.
A6: • DIO range: 54–77 days — lowest in peer group.
A7: • DPO constrained by TSMC pricing power; Qualcomm (88d DPO) is best achievable at scale.
A8: • CCC structurally 80–160 days lower than IDMs due to absence of manufacturing WIP.
A9: Foundry (TSMC)
A10: • Pure contract manufacturer. Inventory = entirely WIP (8–12 week fab cycle on N3/N5/N7).
A11: • DIO 137 days reflects physical wafer processing time — structurally unavoidable.
A12: • OCF/Revenue = 62% (CRR best in group) driven by $20–25B annual D&A add-back + pricing power.
... A55: 5. Despite limitations, the group is academically valid: same end-markets, customers, input costs, full model spectrum.

Sheet 9 Key Insights
A1: STEP 9 — KEY INSIGHTS SUMMARY TABLE
A2: Metric | B2: Best Company | C2: Best Value | D2: Worst Company | E2: Worst Value | F2: One-Line Reason
A3: DSO | B3: =INDEX('3 Metrics'!$A$3:$A$12,MATCH(MIN('3 Metrics'!$H$3:$H$12),'3 Metrics'!$H$3:$H$12,0)) | C3: =TEXT(MIN('3 Metrics'!$H$3:$H$12),"0.00")&" days" | D3: =INDEX('3 Metrics'!$A$3:$A$12,MATCH(MAX('3 Metrics'!$H$3:$H$12),'3 Metrics'!$H$3:$H$12,0)) | E3: =TEXT(MAX('3 Metrics'!$H$3:$H$12),"0.00")&" days" | F3: Intel's hyperscaler/enterprise customers pay quickly; Infineon's automotive OEMs demand long credit terms
A4: AR Turns | B4: =INDEX('3 Metrics'!$A$3:$A$12,MATCH(MAX('3 Metrics'!$I$3:$I$12),'3 Metrics'!$I$3:$I$12,0)) | C4: =TEXT(MAX('3 Metrics'!$I$3:$I$12),"0.00")&"×" | D4: =INDEX('3 Metrics'!$A$3:$A$12,MATCH(MIN('3 Metrics'!$I$3:$I$12),'3 Metrics'!$I$3:$I$12,0)) | E4: =TEXT(MIN('3 Metrics'!$I$3:$I$12),"0.00")&"×" | F4: Mirror of DSO: Intel collects receivables ~2× faster than Infineon on a revenue-adjusted basis
A5: DIO | B5: =INDEX('3 Metrics'!$A$3:$A$12,MATCH(MIN('3 Metrics'!$J$3:$J$12),'3 Metrics'!$J$3:$J$12,0)) | C5: =TEXT(MIN('3 Metrics'!$J$3:$J$12),"0.00")&" days" | D5: =INDEX('3 Metrics'!$A$3:$A$12,MATCH(MAX('3 Metrics'!$J$3:$J$12),'3 Metrics'!$J$3:$J$12,0)) | E5: =TEXT(MAX('3 Metrics'!$J$3:$J$12),"0.00")&" days" | F5: Fabless Qualcomm holds zero WIP; Infineon carries 40+ weeks of IDM inventory during auto demand collapse
A6: DPO | B6: =INDEX('3 Metrics'!$A$3:$A$12,MATCH(MAX('3 Metrics'!$K$3:$K$12),'3 Metrics'!$K$3:$K$12,0)) | C6: =TEXT(MAX('3 Metrics'!$K$3:$K$12),"0.00")&" days" | D6: =INDEX('3 Metrics'!$A$3:$A$12,MATCH(MIN('3 Metrics'!$K$3:$K$12),'3 Metrics'!$K$3:$K$12,0)) | E6: =TEXT(MIN('3 Metrics'!$K$3:$K$12),"0.00")&" days" | F6: Qualcomm leverages TSMC/foundry scale for 88-day terms; TXN's IDM model generates fewer external payables
A7: CCC | B7: =INDEX('3 Metrics'!$A$3:$A$12,MATCH(MIN('3 Metrics'!$L$3:$L$12),'3 Metrics'!$L$3:$L$12,0)) | C7: =TEXT(MIN('3 Metrics'!$L$3:$L$12),"0.00")&" days" | D7: =INDEX('3 Metrics'!$A$3:$A$12,MATCH(MAX('3 Metrics'!$L$3:$L$12),'3 Metrics'!$L$3:$L$12,0)) | E7: =TEXT(MAX('3 Metrics'!$L$3:$L$12),"0.00")&" days" | F7: Qualcomm's fabless model + highest DPO nearly offsets DSO+DIO; Infineon's bloated inventory locks cash for 240+ days
A8: CRR | B8: =INDEX('3 Metrics'!$A$3:$A$12,MATCH(MAX('3 Metrics'!$M$3:$M$12),'3 Metrics'!$M$3:$M$12,0)) | C8: =TEXT(MAX('3 Metrics'!$M$3:$M$12),"0.00")&"%" | D8: =INDEX('3 Metrics'!$A$3:$A$12,MATCH(MIN('3 Metrics'!$M$3:$M$12),'3 Metrics'!$M$3:$M$12,0)) | E8: =TEXT(MIN('3 Metrics'!$M$3:$M$12),"0.00")&"%" | F8: TSMC adds back $20–25B D&A for exceptional OCF; AMD's R&D/SG&A reinvestment limits OCF conversion
A9: Operating NWC (absolute) | B9: =INDEX('3 Metrics'!$A$3:$A$12,MATCH(MIN('3 Metrics'!$D$3:$D$12),'3 Metrics'!$D$3:$D$12,0)) | C9: ="$"&TEXT(MIN('3 Metrics'!$D$3:$D$12),"#,##0")&"M" | D9: =INDEX('3 Metrics'!$A$3:$A$12,MATCH(MAX('3 Metrics'!$D$3:$D$12),'3 Metrics'!$D$3:$D$12,0)) | E9: ="$"&TEXT(MAX('3 Metrics'!$D$3:$D$12),"#,##0")&"M" | F9: NXP is smallest-revenue IDM with tight WC; TSMC's foundry WIP inventory dominates balance sheet
A10: NWC% | B10: =INDEX('3 Metrics'!$A$3:$A$12,MATCH(MIN('3 Metrics'!$E$3:$E$12),'3 Metrics'!$E$3:$E$12,0)) | C10: =TEXT(MIN('3 Metrics'!$E$3:$E$12),"0.00")&"%" | D10: =INDEX('3 Metrics'!$A$3:$A$12,MATCH(MAX('3 Metrics'!$E$3:$E$12),'3 Metrics'!$E$3:$E$12,0)) | E10: =TEXT(MAX('3 Metrics'!$E$3:$E$12),"0.00")&"%" | F10: Fabless model minimises operating NWC/revenue; Infineon's revenue-adjusted inventory burden is highest in group
A11: WC Intensity | B11: =INDEX('3 Metrics'!$A$3:$A$12,MATCH(MIN('3 Metrics'!$F$3:$F$12),'3 Metrics'!$F$3:$F$12,0)) | C11: =TEXT(MIN('3 Metrics'!$F$3:$F$12),"0.00")&"" | D11: =INDEX('3 Metrics'!$A$3:$A$12,MATCH(MAX('3 Metrics'!$F$3:$F$12),'3 Metrics'!$F$3:$F$12,0)) | E11: =TEXT(MAX('3 Metrics'!$F$3:$F$12),"0.00")&"" | F11: Intel's flat revenue + tightly managed balance-sheet WC keeps intensity low; TSMC hoards cash for capex commitments
A12: Current Ratio | B12: =INDEX('3 Metrics'!$A$3:$A$12,MATCH(MAX('3 Metrics'!$G$3:$G$12),'3 Metrics'!$G$3:$G$12,0)) | C12: =TEXT(MAX('3 Metrics'!$G$3:$G$12),"0.00")&"" | D12: =INDEX('3 Metrics'!$A$3:$A$12,MATCH(MIN('3 Metrics'!$G$3:$G$12),'3 Metrics'!$G$3:$G$12,0)) | E12: =TEXT(MIN('3 Metrics'!$G$3:$G$12),"0.00")&"" | F12: NVIDIA's AI-driven cash hoard inflates ratio; Intel's restructuring payables compress it — neither is abnormal
A13: Overall Best Practice (V-A & V-B) | B13: =INDEX('5 Scoring Model'!$A$4:$A$13,MATCH(1,'5 Scoring Model'!$H$4:$H$13,0)) | C13: ="Rank #1 V-A & Rank #"&INDEX('5 Scoring Model'!$J$4:$J$13,MATCH(1,'5 Scoring Model'!$H$4:$H$13,0))&" V-B" | D13: =INDEX('5 Scoring Model'!$A$4:$A$13,MATCH(MAX('5 Scoring Model'!$H$4:$H$13),'5 Scoring Model'!$H$4:$H$13,0)) | E13: ="Rank #"&MAX('5 Scoring Model'!$H$4:$H$13)&" both versions" | F13: NVIDIA's AI revenue surge structurally compresses all flow ratios; Infineon faces simultaneous inventory bloat + revenue decline

Sheet 10 Sources & Assumptions
A1: DATA SOURCES
A2: # | B2: Company | C2: Filing Type | D2: Document | E2: Notes | F2: URL (SEC EDGAR / Investor Relations)
A3: 1 | B3: NVIDIA | C3: 10-K | D3: Form 10-K FY2025 (yr ended Jan 26 2025) — SEC EDGAR CIK 0001045810 | F3: EDGAR 10-K — NVIDIA (CIK 1045810)
A4: 2 | B4: AMD | C4: 10-K | D4: Form 10-K FY2024 (yr ended Dec 28 2024) — SEC EDGAR CIK 0000002488 | F4: EDGAR 10-K — AMD (CIK 2488)
A5: 3 | B5: Intel | C5: 10-K | D5: Form 10-K FY2024 (yr ended Dec 28 2024) — SEC EDGAR CIK 0000050863 | E5: COGS includes ~$5.2B impairment | F5: EDGAR 10-K — Intel (CIK 50863)
A6: 4 | B6: Texas Instruments | C6: 10-K | D6: Form 10-K FY2024 (yr ended Dec 31 2024) — SEC EDGAR CIK 0000097476 | F6: EDGAR 10-K — Texas Instruments (CIK 97476)
A7: 5 | B7: Qualcomm | C7: 10-K | D7: Form 10-K FY2024 (yr ended Sep 29 2024) — SEC EDGAR CIK 0000804328 | E7: FY = Oct–Sep | F7: EDGAR 10-K — Qualcomm (CIK 804328)
A8: 6 | B8: NXP Semiconductors | C8: 20-F | D8: Form 20-F FY2024 (yr ended Dec 31 2024) — SEC EDGAR CIK 0001413447 | E8: US GAAP, USD | F8: EDGAR 20-F — NXP Semiconductors (CIK 1413447)
A9: 7 | B9: TSMC | C9: 20-F | D9: Form 20-F FY2024 (yr ended Dec 31 2024) — SEC EDGAR CIK 0001046179 | E9: IFRS, TWD→USD | F9: EDGAR 20-F — TSMC (CIK 1046179)
A10: 8 | B10: Micron Technology | C10: 10-K | D10: Form 10-K FY2024 (yr ended Aug 29 2024) — SEC EDGAR CIK 0000723125 | E10: FY = Sep–Aug | F10: EDGAR 10-K — Micron Technology (CIK 723125)
A11: 9 | B11: STMicroelectronics | C11: 20-F | D11: Form 20-F FY2024 (yr ended Dec 31 2024) — SEC EDGAR CIK 0000912093 | E11: IFRS, reported USD | F11: EDGAR 20-F — STMicroelectronics (CIK 912093)
A12: 10 | B12: Infineon Technologies | C12: Annual Report / 20-F | D12: Annual Report FY2024 (yr ended Sep 30 2024) — IFRS, EUR→USD | E12: FY = Oct–Sep | F12: Infineon Annual Report (IR page)
A15: MASTER ASSUMPTIONS LOG
A16: # | B16: Assumption | C16: Companies Affected | D16: Reason | E16: Verification Required?
A17: A1 | B17: NVIDIA FY2025 (Jan 26 2025) = current year; FY2024 (Jan 28 2024) = prior year | C17: NVIDIA | D17: Most recent annual covering CY2024 operations | E17: No
A18: A2 | B18: TSMC FX: 32.0 TWD/USD (FY2024), 31.1 TWD/USD (FY2023) | C18: TSMC | D18: Annual average exchange rates [A] | E18: Yes — verify vs. TSMC 20-F stated rate
A19: A3 | B19: Infineon FX: 1.085 USD/EUR (FY2024), 1.082 USD/EUR (FY2023) | C19: Infineon | D19: Annual average EUR/USD for Oct–Sep periods [A] | E19: Yes — verify vs. Infineon Annual Report
A20: A4 | B20: COGS = Revenue − Gross Profit where not directly stated | C20: Intel, Micron | D20: Standard accounting identity; used as cross-check | E20: No
A21: A5 | B21: Intel FY2024 COGS includes ~$5.2B asset impairment; not adjusted | C21: Intel | D21: Reported unadjusted per 10-K; gross margin depressed | E21: Flag in all Intel metric comparisons
A22: A6 | B22: Micron FY2023 COGS = $17,446M (negative gross profit of −$1,906M) | C22: Micron | D22: Memory price collapse; reported figures used without adjustment | E22: Flag DIO as cyclically distorted
A23: A7 | B23: TXN DIO of 218.70d reflects deliberate strategic inventory build — not operational failure | C23: TXN | D23: Management guided 20–25 weeks finished-goods target | E23: Note in all TXN comparisons
A24: A8 | B24: Balance sheet totals (Total CA, CL, Cash, ST Debt) are approximated [A] | C24: All | D24: Operating NWC metrics use precisely sourced AR/Inv/AP/COGS/Revenue | E24: Verify balance sheet totals vs. filings
A25: A9 | B25: TSMC OCF estimated at ~$56,250M (NT$1,800B × 32.0 TWD/USD) | C25: TSMC | D25: Estimated from NT$ OCF [A] | E25: Yes — verify vs. TSMC 20-F cash flow statement
A26: A10 | B26: Prior-year data available for all 10 companies; no single-year averaging needed | C26: All | D26: Both current-year and prior-year AR, Inv, AP, Revenue, COGS sourced | E26: No
A27: A11 | B27: Operating NWC uses trade AR, trade inventory, trade AP only — no tax/derivative/financing items | C27: All | D27: Per methodology specification | E27: No
A28: A12 | B28: Infineon FY2024 = Oct 2023–Sep 2024; FY2023 = Oct 2022–Sep 2023 | C28: Infineon | D28: Infineon fiscal year runs Oct–Sep | E28: No

Sheet 11 Formula Reference
A1: STEP 11 — FORMULA REFERENCE | All formulas, explanations, and data source references ⚡ NOTE: As of this version all calculated cells in Sheets 2–6 and 9 use live Excel formulas linked to Sheet 1 raw data — no hardcoded computed values. Select any cell in those sheets to see and audit the formula in the formula bar.
A2: # | B2: Metric / Variable | C2: Formula | D2: Short Explanation | E2: Source Sheet / Cells | F2: Data Origin | G2: Notes / Flags
A3: A — AVERAGE BALANCE CALCULATIONS (Sheet: 2 Average Balances)
A4: A1 | B4: Average Accounts Receivable (Avg AR) | C4: Avg AR = (AR_CY + AR_PY) / 2 | D4: Simple two-period average smooths seasonality and point-in-time reporting differences. | E4: Sheet "2 Average Balances" col B AR data: Sheet "1 Raw Data" rows 29–39 cols B–C | F4: Company 10-K / 20-F — Balance Sheet (Trade Receivables, net) | G4: Use net AR (after allowance). TSMC values converted from TWD at annual avg FX.
A5: A2 | B5: Average Inventory (Avg Inventory) | C5: Avg Inv = (Inventory_CY + Inventory_PY) / 2 | D5: Averages opening and closing inventory to reduce distortion from period-end builds. | E5: Sheet "2 Average Balances" col C Inv data: Sheet "1 Raw Data" rows 29–39 cols D–E | F5: Company 10-K / 20-F — Balance Sheet (Inventories) | G5: ⚠ TXN: strategic build. ⚠ Micron FY23: memory trough inflates avg.
A6: A3 | B6: Average Accounts Payable (Avg AP) | C6: Avg AP = (AP_CY + AP_PY) / 2 | D6: Two-period average of trade payables to align with the COGS denominator used in DPO. | E6: Sheet "2 Average Balances" col D AP data: Sheet "1 Raw Data" rows 29–39 cols F–G | F6: Company 10-K / 20-F — Balance Sheet (Trade Payables / Accounts Payable) | G6: Trade AP only; excludes accrued expenses and financing payables.
A7: A4 | B7: Average COGS (Avg COGS) | C7: Avg COGS = (COGS_CY + COGS_PY) / 2 | D7: Used as the denominator for DIO and DPO to neutralise single-year COGS anomalies. | E7: Sheet "2 Average Balances" col E COGS data: Sheet "1 Raw Data" rows 16–26 cols D–E | F7: Company 10-K / 20-F — Income Statement (Cost of Revenue / Cost of Goods Sold) | G7: Intel: COGS includes ~$5.2B impairment (not adjusted). Micron FY23 COGS > Revenue (gross loss).
A8: A5 | B8: Average Revenue (Avg Revenue) | C8: Avg Revenue = (Revenue_CY + Revenue_PY) / 2 | D8: Used as DSO denominator; smooths hyper-growth companies (NVIDIA +114% YoY). | E8: Sheet "2 Average Balances" col F Revenue data: Sheet "1 Raw Data" rows 16–26 cols B–C | F8: Company 10-K / 20-F — Income Statement (Net Revenue / Net Sales) | G8: TSMC: NT$ revenues converted at annual avg rate. Infineon: EUR converted at 1.085 USD/EUR.
A9: B — WORKING CAPITAL METRICS (Sheet: 3 Metrics, cols B–G)
A10: B1 | B10: Working Capital (WC) | C10: WC = Total Current Assets − Total Current Liabilities | D10: Broadest liquidity measure; shows net short-term resources after all near-term obligations. | E10: Sheet "3 Metrics" col B CA/CL: Sheet "1 Raw Data" rows 40–51 cols B, E | F10: 10-K / 20-F Balance Sheet — Current Assets & Current Liabilities totals | G10: [A] CA and CL totals are approximated where not explicitly broken out.
A11: B2 | B11: Balance Sheet NWC (BS NWC) | C11: BS NWC = (Total CA − Cash & ST Investments) − (Total CL − ST Debt) | D11: Strips financing items (cash, short-term debt) from WC to reveal the operating funding gap. | E11: Sheet "3 Metrics" col C Cash, ST Debt: Sheet "1 Raw Data" rows 40–51 cols C, G | F11: 10-K / 20-F Balance Sheet | G11: [A] Cash & ST Inv and ST Debt values approximated for several companies.
A12: B3 | B12: Operating NWC (Op. NWC) | C12: Op. NWC = Trade AR + Inventory − Trade AP | D12: Isolates the cash tied up purely in the trade cycle — the most actionable metric. | E12: Sheet "3 Metrics" col D AR/Inv/AP: Sheet "1 Raw Data" rows 28–39 | F12: 10-K / 20-F — AR (net), Inventories, Accounts Payable (CY values only) | G12: Uses current-year balances only. Avg Op. NWC used in gap analysis (Sheet 6).
A13: B4 | B13: NWC as % of Revenue (NWC%) | C13: NWC% = Op. NWC / Revenue_CY × 100 | D13: Revenue-normalised view; allows fair size-adjusted comparison across companies. | E13: Sheet "3 Metrics" col E Op. NWC: col D same row; Revenue CY: Sheet "1 Raw Data" col B rows 17–26 | F13: Derived — no direct filing source | G13: Lower % = more capital-efficient. Qualcomm best (11.5%), Infineon worst (46.7%).
A14: B5 | B14: WC Intensity | C14: WC Intensity = WC / Revenue_CY (decimal, not %) where WC = Total CA − Total CL | D14: Same as NWC% but expressed as a ratio. A value of 0.20 = $0.20 of WC per $1 of revenue. | E14: Sheet "3 Metrics" col F WC: col B same row; Revenue CY: Sheet "1 Raw Data" col B rows 17–26 | F14: Derived — no direct filing source | G14: Equivalent to NWC% ÷ 100. Used in scoring model.
A15: B6 | B15: Current Ratio | C15: Current Ratio = Total CA / Total CL | D15: Standard short-term solvency test. >1 means current assets cover current liabilities. | E15: Sheet "3 Metrics" col G CA/CL: Sheet "1 Raw Data" rows 40–51 | F15: 10-K / 20-F Balance Sheet | G15: [A] Based on approximated CA/CL. A ratio of 1.5–3.0 is generally considered healthy.
A16: C — ACTIVITY / EFFICIENCY RATIOS (Sheet: 3 Metrics, cols H–M)
A17: C1 | B17: Days Sales Outstanding (DSO) | C17: DSO = Avg AR / (Revenue_CY / 365) | D17: Average number of days to collect cash after a sale. Lower = faster cash collection. | E17: Sheet "3 Metrics" col H Avg AR: Sheet "2" col B; Revenue CY: Sheet "1 Raw Data" col B rows 17–26 | F17: Derived from 10-K / 20-F AR and Revenue figures | G17: Best: Intel 35.5d (fast enterprise pay). Worst: Infineon 71.0d (auto OEM credit terms).
A18: C2 | B18: Accounts Receivable Turnover (AR Turns) | C18: AR Turns = Revenue_CY / Avg AR (times per year) | D18: How many times per year a company collects its entire AR balance. Higher = better. | E18: Sheet "3 Metrics" col I Revenue CY: Sheet "1 Raw Data" col B rows 17–26; Avg AR: Sheet "2" col B | F18: Derived — no direct filing source | G18: Mathematically inverse of DSO × 365. Used in ranking and scoring as a cross-check.
A19: C3 | B19: Days Inventory Outstanding (DIO) | C19: DIO = Avg Inventory / Avg COGS × 365 | D19: Average days inventory is held before sale. Lower = leaner supply chain. | E19: Sheet "3 Metrics" col J Avg Inv: Sheet "2" col C; Avg COGS: Sheet "2" col E | F19: Derived from 10-K / 20-F Inventory and COGS figures | G19: ⚠ TXN 218.7d = strategic. ⚠ Infineon 243.7d = auto demand collapse. ⚠ Micron 165.4d = cycle.
A20: C4 | B20: Days Payable Outstanding (DPO) | C20: DPO = Avg AP / Avg COGS × 365 | D20: Average days taken to pay suppliers. Higher = better for the buyer (free credit period). | E20: Sheet "3 Metrics" col K Avg AP: Sheet "2" col D; Avg COGS: Sheet "2" col E | F20: Derived from 10-K / 20-F AP and COGS figures | G20: Best: Qualcomm 88.4d. Worst: TXN 22.4d (IDM own-fab model generates fewer trade payables).
A21: C5 | B21: Cash Conversion Cycle (CCC) | C21: CCC = DSO + DIO − DPO (days) | D21: Days from paying suppliers to collecting cash from customers. Lower (or negative) = better. | E21: Sheet "3 Metrics" col L DSO col H, DIO col J, DPO col K | F21: Derived — no direct filing source | G21: Best: Qualcomm 22.1d. Worst: Infineon 240.5d. Negative CCC rare in semiconductors (see Sheet 8).
A22: C6 | B22: Cash Return Ratio (CRR) | C22: CRR = OCF / Revenue_CY × 100 (%) | D22: Fraction of each revenue dollar converted to operating cash. Captures D&A and WC movements. | E22: Sheet "3 Metrics" col M OCF: Sheet "1 Raw Data" rows 40–51 col I; Revenue: col B rows 16–26 | F22: 10-K / 20-F — Cash Flow Statement (Net Cash from Operating Activities) | G22: Best: TSMC 62.2% (massive D&A add-back). Worst: AMD 10.5% (R&D investment). [A] TSMC OCF estimated.
A23: D — CASH POTENTIAL GAP ANALYSIS (Sheet: 6 Cash Potential)
A24: D1 | B24: DSO Lever (USD M) | C24: DSO Lever = (DSO_company − DSO_best) × Avg Revenue / 365 DSO_best = Intel 35.50 days | D24: Cash unlocked if the company reduced DSO to the best-in-class peer level. | E24: Sheet "6 Cash Potential" col C–D DSO values: Sheet "3 Metrics" col H; Avg Revenue: Sheet "2" col F | F24: Derived — no direct filing source | G24: Only calculated for Q3 & Q4 companies. DSO gap = company DSO − 35.50.
A25: D2 | B25: DIO Lever (USD M) | C25: DIO Lever = (DIO_company − DIO_best) × Avg COGS / 365 DIO_best = Qualcomm 54.28 days | D25: Cash unlocked if the company reduced its inventory days to the best-in-class peer level. | E25: Sheet "6 Cash Potential" col E–F DIO values: Sheet "3 Metrics" col J; Avg COGS: Sheet "2" col E | F25: Derived — no direct filing source | G25: ⚠ DIO improvements are subject to business-model constraints (IDM vs. fabless). See Sheet 8.
A26: D3 | B26: DPO Lever (USD M) | C26: DPO Lever = (DPO_best − DPO_company) × Avg COGS / 365 DPO_best = Qualcomm 88.44 days | D26: Additional supplier credit (free cash) available if DPO was extended to best-in-class. | E26: Sheet "6 Cash Potential" col G–H DPO values: Sheet "3 Metrics" col K; Avg COGS: Sheet "2" col E | F26: Derived — no direct filing source | G26: DPO extension requires supplier negotiation; subject to pricing-power constraints.
A27: D4 | B27: Total Cash Potential (USD M) | C27: Total = DSO Lever + DIO Lever + DPO Lever | D27: Combined maximum cash release achievable by closing all three gaps simultaneously. | E27: Sheet "6 Cash Potential" col I | F27: Derived — no direct filing source | G27: Realistic release: 12–24 months. Micron DIO improvement is partially market-dependent.
A28: E — SCORING MODEL (Sheet: 5 Scoring Model)
A29: E1 | B29: Version A Score (Equal Weights) | C29: V-A Score = (DSO_rank + AR_Turns_rank + CCC_rank + CRR_rank + NWC%_rank) / 5 Weight per metric = 20% | D29: Simple average of 5 dimension ranks. Rank 1 = best in group. Lower score = better. | E29: Sheet "5 Scoring Model" col G Ranks: Sheet "4 Rankings" cols B–I | F29: Derived — no direct filing source | G29: Five metrics: DSO, AR Turns, CCC, CRR, NWC%. Equal 20% weight each.
A30: E2 | B30: Version B Score (Sensitivity Weights) | C30: V-B Score = CCC_rank × 0.30 + NWC%_rank × 0.25 + DSO_rank × 0.15 + AR_Turns_rank × 0.15 + CRR_rank × 0.15 | D30: Weighted scoring emphasising the cash cycle (CCC) and NWC efficiency as primary levers. | E30: Sheet "5 Scoring Model" col I Ranks: Sheet "4 Rankings" | F30: Derived — no direct filing source | G30: CCC and NWC% together = 55% of total score, reflecting their importance as strategic levers.
A31: E3 | B31: Quartile Assignment | C31: Q1: V-A Rank 1–3 (Top performers) Q2: V-A Rank 4–5 Q3: V-A Rank 6–8 Q4: V-A Rank 9–10 (Underperformers) Formula: =IF(H<=3,"Q1",IF(H<=5,"Q2",IF(H<=8,"Q3","Q4"))) | D31: Groups companies into performance tiers for strategy and cash-potential analysis. | E31: Sheet "5 Scoring Model" col K | F31: Derived — no direct filing source | G31: Q3 & Q4 companies are analysed further in Sheets 6 and 7 for cash release potential.
A32: F — CURRENCY CONVERSION (Sheet: 1 Raw Data, col H)
A33: F1 | B33: TSMC: TWD → USD (FY2024) | C33: USD value = TWD value ÷ 32.0 | D33: Converts TSMC financials from New Taiwan Dollar to USD using annual average FX rate. | E33: Sheet "1 Raw Data" cell H10 Assumption A2: Sheet "10 Sources & Assumptions" row 18 | F33: Annual average TWD/USD exchange rate for calendar year 2024 [Approximated] | G33: ⚠ [A] Verify vs. TSMC Form 20-F stated average translation rate.
A34: F2 | B34: TSMC: TWD → USD (FY2023) | C34: USD value = TWD value ÷ 31.1 | D34: Prior-year TSMC conversion for two-period average balance calculations. | E34: Sheet "1 Raw Data" cell H10 Assumption A2: Sheet "10 Sources & Assumptions" row 18 | F34: Annual average TWD/USD exchange rate for calendar year 2023 [Approximated] | G34: ⚠ [A] Verify vs. TSMC Form 20-F.
A35: F3 | B35: Infineon: EUR → USD (FY2024) | C35: USD value = EUR value × 1.085 | D35: Converts Infineon financials from Euro to USD. Infineon FY runs Oct 2023 – Sep 2024. | E35: Sheet "1 Raw Data" cell H13 Assumption A3: Sheet "10 Sources & Assumptions" row 19 | F35: Annual average EUR/USD exchange rate for Oct 2023 – Sep 2024 period [Approximated] | G35: ⚠ [A] Verify vs. Infineon Annual Report 2024 stated average rate.
A36: F4 | B36: Infineon: EUR → USD (FY2023) | C36: USD value = EUR value × 1.082 | D36: Prior-year Infineon conversion for two-period averages. | E36: Sheet "1 Raw Data" cell H13 Assumption A3: Sheet "10 Sources & Assumptions" row 19 | F36: Annual average EUR/USD exchange rate for Oct 2022 – Sep 2023 period [Approximated] | G36: ⚠ [A] Verify vs. Infineon Annual Report 2023.
A37: G — DERIVED / RECONSTRUCTED INPUTS (Sheet: 1 Raw Data, col H)
A38: G1 | B38: COGS (where not directly stated) | C38: COGS = Revenue − Gross Profit | D38: Standard accounting identity. Used when COGS line is not separately disclosed on the P&L. | E38: Sheet "1 Raw Data" col H (COGS Method) Assumption A4: Sheet "10" row 20 | F38: Company 10-K — Income Statement (Revenue and Gross Profit are always disclosed) | G38: Applied to: Intel (FY2024) and Micron (FY2023/FY2024). Result cross-checked against disclosed COGS where available.
A39: G2 | B39: Gross Margin (verification) | C39: Gross Margin % = Gross Profit / Revenue × 100 = (Revenue − COGS) / Revenue × 100 | D39: Used to verify COGS figures against disclosed gross margin percentages in filings. | E39: Sheet "1 Raw Data" cols F–G | F39: 10-K / 20-F Income Statement | G39: ⚠ Intel FY2024 gross margin of 32.7% reflects $5.2B impairment in COGS (Assumption A5). ⚠ Micron FY2023 gross margin = −12.3% (gross loss).
A40: G3 | B40: TSMC OCF Estimate | C40: OCF (USD M) = OCF (NT$B) × 1,000 / FX rate OCF ≈ NT$1,800B × 1,000 / 32.0 = $56,250M | D40: TSMC operating cash flow converted from NT$ to USD using annual average FX rate. | E40: Sheet "1 Raw Data" row 48 col I Assumption A9: Sheet "10" row 25 | F40: TSMC Form 20-F — Cash Flow Statement (NT$ figures) [Approximated] | G40: ⚠ [A] Estimate based on NT$ filing. Verify exact USD figure vs. TSMC 20-F cash flow statement.
...

Sheet 12 URL References
A1: STEP 12 — COMPLETE URL REFERENCE LIST | All sources used in this benchmarking report | 64 total reference URLs across 7 sections | All hyperlinks are clickable (Ctrl+Click in Excel)
A2: # | B2: Category | C2: Description | D2: URL (clickable) | E2: Notes
A3: A — PRIMARY FILINGS (U.S. SEC EDGAR — Annual Reports)
A4: A1 | B4: SEC 10-K (NVIDIA) | C4: NVIDIA Corporation — Form 10-K FY2025 (fiscal year ended Jan 26, 2025). Source of Revenue, COGS, AR, Inventory, AP, OCF for NVDA. | D4: EDGAR — NVIDIA 10-K filings (CIK 1045810) | E4: CIK: 0001045810
A5: A2 | B5: SEC 10-K (AMD) | C5: Advanced Micro Devices — Form 10-K FY2024 (fiscal year ended Dec 28, 2024). Source of Revenue, COGS, AR, Inventory, AP, OCF for AMD. | D5: EDGAR — AMD 10-K filings (CIK 2488) | E5: CIK: 0000002488
A6: A3 | B6: SEC 10-K (Intel) | C6: Intel Corporation — Form 10-K FY2024 (fiscal year ended Dec 28, 2024). Note: COGS includes ~$5.2B asset impairment charge (not adjusted in this report). | D6: EDGAR — Intel 10-K filings (CIK 50863) | E6: CIK: 0000050863
A7: A4 | B7: SEC 10-K (Texas Instruments) | C7: Texas Instruments Incorporated — Form 10-K FY2024 (fiscal year ended Dec 31, 2024). DIO elevated due to management-guided strategic inventory build (20–25 weeks target). | D7: EDGAR — Texas Instruments 10-K filings (CIK 97476) | E7: CIK: 0000097476
A8: A5 | B8: SEC 10-K (Qualcomm) | C8: Qualcomm Incorporated — Form 10-K FY2024 (fiscal year ended Sep 29, 2024; FY = Oct–Sep). Best-in-class CCC (22.1d) and DIO (54.3d) in this peer group. | D8: EDGAR — Qualcomm 10-K filings (CIK 804328) | E8: CIK: 0000804328
A9: A6 | B9: SEC 20-F (NXP Semiconductors) | C9: NXP Semiconductors N.V. — Form 20-F FY2024 (fiscal year ended Dec 31, 2024). Reports under US GAAP in USD. Best IDM in peer group (CCC ≈ 100d). | D9: EDGAR — NXP Semiconductors 20-F filings (CIK 1413447) | E9: CIK: 0001413447
A10: A7 | B10: SEC 20-F (TSMC) | C10: Taiwan Semiconductor Manufacturing Company Ltd — Form 20-F FY2024 (fiscal year ended Dec 31, 2024). Reported in New Taiwan Dollars (TWD); converted to USD at 32.0 TWD/USD (FY2024) and 31.1 TWD/USD (FY2023). | D10: EDGAR — TSMC 20-F filings (CIK 1046179) | E10: CIK: 0001046179
A11: A8 | B11: SEC 10-K (Micron Technology) | C11: Micron Technology Inc — Form 10-K FY2024 (fiscal year ended Aug 29, 2024; FY = Sep–Aug). FY2023 had negative gross profit (memory price collapse); DIO is cyclically distorted. | D11: EDGAR — Micron Technology 10-K filings (CIK 723125) | E11: CIK: 0000723125
A12: A9 | B12: SEC 20-F (STMicroelectronics) | C12: STMicroelectronics N.V. — Form 20-F FY2024 (fiscal year ended Dec 31, 2024). Reports under IFRS in USD. | D12: EDGAR — STMicroelectronics 20-F filings (CIK 912093) | E12: CIK: 0000912093
A13: A10 | B13: Annual Report (Infineon) | C13: Infineon Technologies AG — Annual Report FY2024 (fiscal year ended Sep 30, 2024; FY = Oct–Sep). Reports under IFRS in EUR; converted to USD at 1.085 USD/EUR (FY2024) and 1.082 (FY2023). | D13: Infineon Annual Report 2024 (Investor Relations) | E13: Also filed on SEC EDGAR (CIK varies by year)
A14: B — SEC EDGAR FULL-TEXT SEARCH & COMPANY PAGES
A15: B1 | B15: SEC EDGAR Full-Text Search | C15: EDGAR EFTS allows searching all filing text. Use to locate specific line-items (e.g., "accounts receivable", "inventories") within any 10-K or 20-F. | D15: EDGAR Full-Text Search (EFTS) | E15: Replace search term in URL as needed
A16: B2 | B16: SEC EDGAR Company Search | C16: Search any public company by name or CIK number to find all SEC filings. | D16: EDGAR Company Search Portal | E16: General company search portal
A17: B3 | B17: SEC EDGAR Full-Text Filing Search (EFTS) | C17: Primary interface for searching filings by keyword, form type, and date range. | D17: EDGAR EFTS — 10-K / 20-F Filing Search (2024–2025) | E17: 10-K and 20-F filings 2024–2025
A18: C — COMPANY INVESTOR RELATIONS PAGES (Official IR websites)
A19: C1 | B19: NVIDIA Investor Relations | C19: NVIDIA IR page — access to all annual reports, 10-K filings, earnings releases, and financial data tables. | D19: NVIDIA Investor Relations — Annual Reports | E19: Annual reports & SEC filings
A20: C2 | B20: AMD Investor Relations | C20: AMD IR page — annual reports, 10-K, quarterly results. | D20: AMD Investor Relations — Annual Reports | E20: Annual reports & SEC filings
A21: C3 | B21: Intel Investor Relations | C21: Intel IR page — annual reports, 10-K, earnings releases. | D21: Intel Investor Relations — Annual Reports | E21: Annual reports & SEC filings
A22: C4 | B22: Texas Instruments Investor Relations | C22: TXN IR page — annual report, 10-K, earnings releases, capital allocation policy. | D22: Texas Instruments Investor Relations — Annual Reports | E22: Annual reports & SEC filings
A23: C5 | B23: Qualcomm Investor Relations | C23: QCOM IR page — annual report, 10-K, quarterly earnings, supply-chain disclosures. | D23: Qualcomm Investor Relations — Annual Reports | E23: Annual reports & SEC filings
A24: C6 | B24: NXP Semiconductors Investor Relations | C24: NXPI IR page — annual report, 20-F, earnings releases. | D24: NXP Semiconductors Investor Relations — Annual Reports | E24: Annual reports & SEC filings
A25: C7 | B25: TSMC Investor Relations | C25: TSM IR page — annual report, 20-F, earnings, capacity disclosures. | D25: TSMC Investor Relations — Annual Reports | E25: Annual reports & SEC filings
A26: C8 | B26: Micron Technology Investor Relations | C26: MU IR page — annual report, 10-K, earnings releases. | D26: Micron Technology Investor Relations — Annual Reports | E26: Annual reports & SEC filings
A27: C9 | B27: STMicroelectronics Investor Relations | C27: STM IR page — annual report, 20-F, earnings releases. | D27: STMicroelectronics Investor Relations — Annual Reports | E27: Annual reports & SEC filings
A28: C10 | B28: Infineon Technologies Investor Relations | C28: IFX IR page — annual report, earnings releases, sustainability report. | D28: Infineon Technologies Investor Relations — Annual Report | E28: Annual report & SEC filings
A29: D — FOREIGN EXCHANGE RATE DATA SOURCES (TWD/USD and EUR/USD)
A30: D1 | B30: Federal Reserve H.10 Release — Foreign Exchange Rates | C30: US Federal Reserve official annual average exchange rate data. Used for TWD/USD annual average verification (FY2024: 32.0, FY2023: 31.1 TWD/USD). | D30: Federal Reserve H.10 Release — Summary of Daily Exchange Rates | E30: Official Fed FX data — TWD/USD
